2025-06-19 02:50:44,084 [ERROR] in __init__: Unhandled Exception
Traceback (most recent call last):
  File "/home/grove/miniconda3/envs/flask/lib/python3.11/site-packages/sqlalchemy/engine/base.py", line 1967, in _exec_single_context
    self.dialect.do_execute(
  File "/home/grove/miniconda3/envs/flask/lib/python3.11/site-packages/sqlalchemy/engine/default.py", line 941, in do_execute
    cursor.execute(statement, parameters)
psycopg2.OperationalError: server closed the connection unexpectedly
	This probably means the server terminated abnormally
	before or while processing the request.


The above exception was the direct cause of the following exception:

Traceback (most recent call last):
  File "/home/grove/miniconda3/envs/flask/lib/python3.11/site-packages/flask/app.py", line 867, in full_dispatch_request
    rv = self.dispatch_request()
         ^^^^^^^^^^^^^^^^^^^^^^^
  File "/home/grove/miniconda3/envs/flask/lib/python3.11/site-packages/flask/app.py", line 852, in dispatch_request
    return self.ensure_sync(self.view_functions[rule.endpoint])(**view_args)
           ^^^^^^^^^^^^^^^^^^^^^^^^^^^^^^^^^^^^^^^^^^^^^^^^^^^^^^^^^^^^^^^^^
  File "/home/grove/GitHub/iApplications/iSaksham/app/routes/learning.py", line 23, in home
    return render_template('home.html')  # Rendering home.html template
           ^^^^^^^^^^^^^^^^^^^^^^^^^^^^
  File "/home/grove/miniconda3/envs/flask/lib/python3.11/site-packages/flask/templating.py", line 152, in render_template
    return _render(app, template, context)
           ^^^^^^^^^^^^^^^^^^^^^^^^^^^^^^^
  File "/home/grove/miniconda3/envs/flask/lib/python3.11/site-packages/flask/templating.py", line 129, in _render
    app.update_template_context(context)
  File "/home/grove/miniconda3/envs/flask/lib/python3.11/site-packages/flask/app.py", line 480, in update_template_context
    context.update(self.ensure_sync(func)())
                   ^^^^^^^^^^^^^^^^^^^^^^^^
  File "/home/grove/miniconda3/envs/flask/lib/python3.11/site-packages/flask_login/utils.py", line 405, in _user_context_processor
    return dict(current_user=_get_user())
                             ^^^^^^^^^^^
  File "/home/grove/miniconda3/envs/flask/lib/python3.11/site-packages/flask_login/utils.py", line 370, in _get_user
    current_app.login_manager._load_user()
  File "/home/grove/miniconda3/envs/flask/lib/python3.11/site-packages/flask_login/login_manager.py", line 364, in _load_user
    user = self._user_callback(user_id)
           ^^^^^^^^^^^^^^^^^^^^^^^^^^^^
  File "/home/grove/GitHub/iApplications/iSaksham/app/__init__.py", line 96, in load_user
    return User.query.get(int(user_id))
           ^^^^^^^^^^^^^^^^^^^^^^^^^^^^
  File "<string>", line 2, in get
  File "/home/grove/miniconda3/envs/flask/lib/python3.11/site-packages/sqlalchemy/util/deprecations.py", line 386, in warned
    return fn(*args, **kwargs)  # type: ignore[no-any-return]
           ^^^^^^^^^^^^^^^^^^^
  File "/home/grove/miniconda3/envs/flask/lib/python3.11/site-packages/sqlalchemy/orm/query.py", line 1127, in get
    return self._get_impl(ident, loading.load_on_pk_identity)
           ^^^^^^^^^^^^^^^^^^^^^^^^^^^^^^^^^^^^^^^^^^^^^^^^^^
  File "/home/grove/miniconda3/envs/flask/lib/python3.11/site-packages/sqlalchemy/orm/query.py", line 1136, in _get_impl
    return self.session._get_impl(
           ^^^^^^^^^^^^^^^^^^^^^^^
  File "/home/grove/miniconda3/envs/flask/lib/python3.11/site-packages/sqlalchemy/orm/session.py", line 3873, in _get_impl
    return db_load_fn(
           ^^^^^^^^^^^
  File "/home/grove/miniconda3/envs/flask/lib/python3.11/site-packages/sqlalchemy/orm/loading.py", line 694, in load_on_pk_identity
    session.execute(
  File "/home/grove/miniconda3/envs/flask/lib/python3.11/site-packages/sqlalchemy/orm/session.py", line 2362, in execute
    return self._execute_internal(
           ^^^^^^^^^^^^^^^^^^^^^^^
  File "/home/grove/miniconda3/envs/flask/lib/python3.11/site-packages/sqlalchemy/orm/session.py", line 2247, in _execute_internal
    result: Result[Any] = compile_state_cls.orm_execute_statement(
                          ^^^^^^^^^^^^^^^^^^^^^^^^^^^^^^^^^^^^^^^^
  File "/home/grove/miniconda3/envs/flask/lib/python3.11/site-packages/sqlalchemy/orm/context.py", line 305, in orm_execute_statement
    result = conn.execute(
             ^^^^^^^^^^^^^
  File "/home/grove/miniconda3/envs/flask/lib/python3.11/site-packages/sqlalchemy/engine/base.py", line 1418, in execute
    return meth(
           ^^^^^
  File "/home/grove/miniconda3/envs/flask/lib/python3.11/site-packages/sqlalchemy/sql/elements.py", line 515, in _execute_on_connection
    return connection._execute_clauseelement(
           ^^^^^^^^^^^^^^^^^^^^^^^^^^^^^^^^^^
  File "/home/grove/miniconda3/envs/flask/lib/python3.11/site-packages/sqlalchemy/engine/base.py", line 1640, in _execute_clauseelement
    ret = self._execute_context(
          ^^^^^^^^^^^^^^^^^^^^^^
  File "/home/grove/miniconda3/envs/flask/lib/python3.11/site-packages/sqlalchemy/engine/base.py", line 1846, in _execute_context
    return self._exec_single_context(
           ^^^^^^^^^^^^^^^^^^^^^^^^^^
  File "/home/grove/miniconda3/envs/flask/lib/python3.11/site-packages/sqlalchemy/engine/base.py", line 1986, in _exec_single_context
    self._handle_dbapi_exception(
  File "/home/grove/miniconda3/envs/flask/lib/python3.11/site-packages/sqlalchemy/engine/base.py", line 2355, in _handle_dbapi_exception
    raise sqlalchemy_exception.with_traceback(exc_info[2]) from e
  File "/home/grove/miniconda3/envs/flask/lib/python3.11/site-packages/sqlalchemy/engine/base.py", line 1967, in _exec_single_context
    self.dialect.do_execute(
  File "/home/grove/miniconda3/envs/flask/lib/python3.11/site-packages/sqlalchemy/engine/default.py", line 941, in do_execute
    cursor.execute(statement, parameters)
sqlalchemy.exc.OperationalError: (psycopg2.OperationalError) server closed the connection unexpectedly
	This probably means the server terminated abnormally
	before or while processing the request.

[SQL: SELECT "user".id AS user_id, "user".name AS user_name, "user".email AS user_email, "user".password AS user_password, "user".is_active AS user_is_active, "user".is_admin AS user_is_admin, "user".registered_on AS user_registered_on, "user".uuid AS user_uuid 
FROM "user" 
WHERE "user".id = %(pk_1)s]
[parameters: {'pk_1': 2}]
(Background on this error at: https://sqlalche.me/e/20/e3q8)
2025-06-19 02:50:44,112 [ERROR] in __init__: URL: http://127.0.0.1:8080/isaksham/home
2025-06-19 02:50:44,117 [ERROR] in __init__: Payload: N/A
2025-06-19 02:51:40,282 [ERROR] in __init__: Unhandled Exception
Traceback (most recent call last):
  File "/home/grove/miniconda3/envs/flask/lib/python3.11/site-packages/flask/app.py", line 865, in full_dispatch_request
    rv = self.preprocess_request()
         ^^^^^^^^^^^^^^^^^^^^^^^^^
  File "/home/grove/miniconda3/envs/flask/lib/python3.11/site-packages/flask/app.py", line 1239, in preprocess_request
    rv = self.ensure_sync(before_func)()
         ^^^^^^^^^^^^^^^^^^^^^^^^^^^^^^^
  File "/home/grove/GitHub/iApplications/iSaksham/app/__init__.py", line 106, in increment_visit_count
    db.rollback()  # Ensure the database session is clean before each request
    ^^^^^^^^^^^
  File "/home/grove/miniconda3/envs/flask/lib/python3.11/site-packages/flask_sqlalchemy/extension.py", line 1008, in __getattr__
    raise AttributeError(name)
AttributeError: rollback
2025-06-19 02:51:40,296 [ERROR] in __init__: URL: http://127.0.0.1:8080/isaksham/home
2025-06-19 02:51:40,300 [ERROR] in __init__: Payload: N/A
2025-06-19 02:53:03,128 [ERROR] in __init__: Unhandled Exception
Traceback (most recent call last):
  File "/home/grove/miniconda3/envs/flask/lib/python3.11/site-packages/flask/app.py", line 865, in full_dispatch_request
    rv = self.preprocess_request()
         ^^^^^^^^^^^^^^^^^^^^^^^^^
  File "/home/grove/miniconda3/envs/flask/lib/python3.11/site-packages/flask/app.py", line 1239, in preprocess_request
    rv = self.ensure_sync(before_func)()
         ^^^^^^^^^^^^^^^^^^^^^^^^^^^^^^^
  File "/home/grove/GitHub/iApplications/iSaksham/app/__init__.py", line 111, in increment_visit_count
    db.rollback()  # Ensure the database session is clean before each request
    ^^^^^^^^^^^
  File "/home/grove/miniconda3/envs/flask/lib/python3.11/site-packages/flask_sqlalchemy/extension.py", line 1008, in __getattr__
    raise AttributeError(name)
AttributeError: rollback
2025-06-19 02:53:03,141 [ERROR] in __init__: URL: http://127.0.0.1:8080/isaksham/home
2025-06-19 02:53:03,146 [ERROR] in __init__: Payload: N/A
2025-06-19 02:53:04,787 [ERROR] in __init__: Unhandled Exception
Traceback (most recent call last):
  File "/home/grove/miniconda3/envs/flask/lib/python3.11/site-packages/flask/app.py", line 865, in full_dispatch_request
    rv = self.preprocess_request()
         ^^^^^^^^^^^^^^^^^^^^^^^^^
  File "/home/grove/miniconda3/envs/flask/lib/python3.11/site-packages/flask/app.py", line 1239, in preprocess_request
    rv = self.ensure_sync(before_func)()
         ^^^^^^^^^^^^^^^^^^^^^^^^^^^^^^^
  File "/home/grove/GitHub/iApplications/iSaksham/app/__init__.py", line 111, in increment_visit_count
    db.rollback()  # Ensure the database session is clean before each request
    ^^^^^^^^^^^
  File "/home/grove/miniconda3/envs/flask/lib/python3.11/site-packages/flask_sqlalchemy/extension.py", line 1008, in __getattr__
    raise AttributeError(name)
AttributeError: rollback
2025-06-19 02:53:04,800 [ERROR] in __init__: URL: http://127.0.0.1:8080/isaksham/static/css/base.css
2025-06-19 02:53:04,805 [ERROR] in __init__: Payload: N/A
